ERROR:asyncio:Task exception was never retrieved
future: <Task finished name='Task-1' coro=<main() done, defined at D:\Temp\p2p-broadcast\app\main.py:9> exception=FileNotFoundError(2, 'No such file or directory')>
Traceback (most recent call last):
  File "D:\Temp\p2p-broadcast\app\main.py", line 17, in main
    in_file = await aiofiles.open("/dev/stdin", "r")
  File "D:\conda\lib\site-packages\aiofiles\base.py", line 70, in __await__
    resp = yield from self._coro
  File "D:\conda\lib\site-packages\aiofiles\threadpool\__init__.py", line 80, in _open
    f = yield from loop.run_in_executor(executor, cb)
  File "D:\conda\lib\concurrent\futures\thread.py", line 52, in run
    result = self.fn(*self.args, **self.kwargs)
FileNotFoundError: [Errno 2] No such file or directory: '/dev/stdin'
INFO:root:Initialize transport
INFO:root:Initialize Telegram transport
INFO:root:Authorizing into Telegram...
INFO:telethon.network.mtprotosender:Connecting to 149.154.167.51:443/TcpFull...
INFO:telethon.network.mtprotosender:Connection to 149.154.167.51:443/TcpFull complete!
INFO:root:Code request sent
INFO:root:Password required
INFO:root:Password incorrect
ERROR:asyncio:Task exception was never retrieved
future: <Task finished name='Task-1' coro=<main() done, defined at main.py:9> exception=EastablishTransportError()>
Traceback (most recent call last):
  File "/mnt/d/temp/p2p-broadcast/app/telegram_transport.py", line 62, in authorize
    await self.client.sign_in(password=self.config["password"])
  File "/home/vetand/.local/lib/python3.8/site-packages/telethon/client/auth.py", line 368, in sign_in
    result = await self(request)
  File "/home/vetand/.local/lib/python3.8/site-packages/telethon/client/users.py", line 30, in __call__
    return await self._call(self._sender, request, ordered=ordered)
  File "/home/vetand/.local/lib/python3.8/site-packages/telethon/client/users.py", line 84, in _call
    result = await future
telethon.errors.rpcerrorlist.PasswordHashInvalidError: The password (and thus its hash value) you entered is invalid (caused by CheckPasswordRequest)

During handling of the above exception, another exception occurred:

Traceback (most recent call last):
  File "main.py", line 30, in main
    await transport.establish()
  File "/mnt/d/temp/p2p-broadcast/app/telegram_transport.py", line 49, in establish
    await self.authorize()
  File "/mnt/d/temp/p2p-broadcast/app/telegram_transport.py", line 65, in authorize
    raise EastablishTransportError()
transport.EastablishTransportError
INFO:root:Initialize transport
INFO:root:Initialize Telegram transport
INFO:root:Authorizing into Telegram...
INFO:telethon.network.mtprotosender:Connecting to 149.154.167.51:443/TcpFull...
INFO:telethon.network.mtprotosender:Connection to 149.154.167.51:443/TcpFull complete!
WARNING:telethon.client.users:Telegram is having internal issues AuthRestartError: Restart the authorization process (caused by SendCodeRequest)
INFO:root:Code request sent
INFO:root:Password required
INFO:root:Authorized to Telegram successfully
INFO:root:Initialize transport
INFO:root:Initialize TCP transport
INFO:root:Starting up a TCP server...
INFO:root:TCP server started!
ERROR:asyncio:Task exception was never retrieved
future: <Task finished name='Task-1' coro=<main() done, defined at main.py:9> exception=IndexError('list index out of range')>
Traceback (most recent call last):
  File "main.py", line 36, in main
    type = l[0]
IndexError: list index out of range
INFO:root:Initialize transport
INFO:root:Initialize Telegram transport
INFO:root:Authorizing into Telegram...
INFO:telethon.network.mtprotosender:Connecting to 149.154.167.51:443/TcpFull...
INFO:telethon.network.mtprotosender:Connection to 149.154.167.51:443/TcpFull complete!
INFO:root:Authorized to Telegram successfully
INFO:root:Initialize transport
INFO:root:Initialize TCP transport
INFO:root:Starting up a TCP server...
INFO:root:TCP server started!
INFO:root:Initialize transport
INFO:root:Initialize Telegram transport
INFO:root:Authorizing into Telegram...
INFO:telethon.network.mtprotosender:Connecting to 149.154.167.51:443/TcpFull...
INFO:telethon.network.mtprotosender:Connection to 149.154.167.51:443/TcpFull complete!
INFO:root:Authorized to Telegram successfully
INFO:root:Initialize transport
INFO:root:Initialize TCP transport
INFO:root:Starting up a TCP server...
INFO:root:TCP server started!
INFO:root:Initialize transport
INFO:root:Initialize Telegram transport
INFO:root:Authorizing into Telegram...
INFO:telethon.network.mtprotosender:Connecting to 149.154.167.51:443/TcpFull...
INFO:telethon.network.mtprotosender:Connection to 149.154.167.51:443/TcpFull complete!
INFO:root:Authorized to Telegram successfully
INFO:root:Initialize transport
INFO:root:Initialize TCP transport
INFO:root:Starting up a TCP server...
INFO:root:TCP server started!
INFO:root:Received message: Так, ну раз уж сообщения остаются в телеге, то нужно таки их как-то зашифровать, хоть симметричной фигнёй какой
